Workbook

Sheet Sale Forecasting (12 months)
A1: Sales Forecasting 1-Year (2023)
A2: [Company's Name] ​​​​​​​​​​ [Forecast Start Date]
B3: Jan | C3: Feb | D3: Mar | E3: Apr | F3: May | G3: Jun | H3: Jul | I3: Aug | J3: Sep | K3: Oct | L3: Nov | M3: Dec | N3: 1-Year
A4: Sale Revenue
A5: Units Sold | N5: Total Units Sold
A6: Product/Service A | B6: 250 | C6: 300 | D6: 340 | E6: 380 | F6: 400 | G6: 420 | H6: 500 | I6: 550 | J6: 650 | K6: 700 | L6: 800 | M6: 1000 | N6: =SUM(B6:M6) -> 6290
A7: Product/Service B
A8: Product/Service C
A9: Unit Price | N9: Avg Unit Price
A10: Product/Service A | B10: 20 | C10: 20 | D10: 20 | E10: 20 | F10: 20 | G10: 20 | H10: 20 | I10: 20 | J10: 20 | K10: 20 | L10: 20 | M10: 20 | N10: =AVERAGE(B10:M10) -> 20
A11: Product/Service B
A12: Product/Service C
A13: Revenue | B13: (Units Sold * Unit Price) | N13: Total Revenue
A14: Product/Service A | B14: =B6*B10 -> 5000 | C14: =C6*C10 -> 6000 | D14: =D6*D10 -> 6800 | E14: =E6*E10 -> 7600 | F14: =F6*F10 -> 8000 | G14: =G6*G10 -> 8400 | H14: =H6*H10 -> 10000 | I14: =I6*I10 -> 11000 | ... N14: =N6*N10 -> 125800
A15: Product/Service B | B15: =B7*B11 -> 0 | C15: =C7*C11 -> 0 | D15: =D7*D11 -> 0 | E15: =E7*E11 -> 0 | F15: =F7*F11 -> 0 | G15: =G7*G11 -> 0 | H15: =H7*H11 -> 0 | I15: =I7*I11 -> 0 | ... N15: =N7*N11 -> 0
A16: Product/Service C | B16: =B8*B12 -> 0 | C16: =C8*C12 -> 0 | D16: =D8*D12 -> 0 | E16: =E8*E12 -> 0 | F16: =F8*F12 -> 0 | G16: =G8*G12 -> 0 | H16: =H8*H12 -> 0 | I16: =I8*I12 -> 0 | ... N16: =N8*N12 -> 0
A17: Total Revenue | B17: =SUM(B14:B16) -> 5000 | C17: =SUM(C14:C16) -> 6000 | D17: =SUM(D14:D16) -> 6800 | E17: =SUM(E14:E16) -> 7600 | F17: =SUM(F14:F16) -> 8000 | G17: =SUM(G14:G16) -> 8400 | H17: =SUM(H14:H16) -> 10000 | I17: =SUM(I14:I16) -> 11000 | ... N17: =SUM(N14:N16) -> 125800
A18: Unit COGS (Cost of Good Sold) | N18: Avg COGS
A19: Product/Service A | B19: 15 | C19: 15 | D19: 15 | E19: 15 | F19: 15 | G19: 15 | H19: 15 | I19: 15 | J19: 15 | K19: 15 | L19: 15 | M19: 15 | N19: =AVERAGE(B19:M19) -> 15
A20: Product/Service B
A21: Product/Service C
A22: COGS | B22: (Units Sold * Unit COGS) | N22: Total COGS
A23: Product/Service A | B23: =B19*B6 -> 3750 | C23: =C19*C6 -> 4500 | D23: =D19*D6 -> 5100 | E23: =E19*E6 -> 5700 | F23: =F19*F6 -> 6000 | G23: =G19*G6 -> 6300 | H23: =H19*H6 -> 7500 | I23: =I19*I6 -> 8250 | ... N23: =N19*N6 -> 94350
A24: Product/Service B
A25: Product/Service C
A26: Total COGS | B26: =SUM(B23:B25) -> 3750 | C26: =SUM(C23:C25) -> 4500 | D26: =SUM(D23:D25) -> 5100 | E26: =SUM(E23:E25) -> 5700 | F26: =SUM(F23:F25) -> 6000 | G26: =SUM(G23:G25) -> 6300 | H26: =SUM(H23:H25) -> 7500 | I26: =SUM(I23:I25) -> 8250 | ... N26: =SUM(N23:N25) -> 94350
A27: Margin Per Unit | B27: (Unit Price - Unit COGS) | N27: Avg COGS
A28: Product/Service A | B28: =B10-B19 -> 5 | C28: =C10-C19 -> 5 | D28: =D10-D19 -> 5 | E28: =E10-E19 -> 5 | F28: =F10-F19 -> 5 | G28: =G10-G19 -> 5 | H28: =H10-H19 -> 5 | I28: =I10-I19 -> 5 | ... N28: =N10-N19 -> 5
A29: Product/Service B | B29: =B11-B20 -> 0 | C29: =C11-C20 -> 0 | D29: =D11-D20 -> 0 | E29: =E11-E20 -> 0 | F29: =F11-F20 -> 0 | G29: =G11-G20 -> 0 | H29: =H11-H20 -> 0 | I29: =I11-I20 -> 0 | ... M29: =M11-M20 -> 0
A30: Product/Service C | B30: =B12-B21 -> 0 | C30: =C12-C21 -> 0 | D30: =D12-D21 -> 0 | E30: =E12-E21 -> 0 | F30: =F12-F21 -> 0 | G30: =G12-G21 -> 0 | H30: =H12-H21 -> 0 | I30: =I12-I21 -> 0 | ... M30: =M12-M21 -> 0
A31: Gross Profit | B31: (Revenue - COGS or Margin Per Unit * Unit Sold) | N31: Total Gross Profit
A32: Product/Service A | B32: =B28*B6 -> 1250 | C32: =C28*C6 -> 1500 | D32: =D28*D6 -> 1700 | E32: =E28*E6 -> 1900 | F32: =F28*F6 -> 2000 | G32: =G28*G6 -> 2100 | H32: =H28*H6 -> 2500 | I32: =I28*I6 -> 2750 | ... N32: =N28*N6 -> 31450
A33: Product/Service B | B33: =B29*B7 -> 0 | C33: =C29*C7 -> 0 | D33: =D29*D7 -> 0 | E33: =E29*E7 -> 0 | F33: =F29*F7 -> 0 | G33: =G29*G7 -> 0 | H33: =H29*H7 -> 0 | I33: =I29*I7 -> 0 | ... M33: =M29*M7 -> 0
A34: Product/Service C | B34: =B30*B8 -> 0 | C34: =C30*C8 -> 0 | D34: =D30*D8 -> 0 | E34: =E30*E8 -> 0 | F34: =F30*F8 -> 0 | G34: =G30*G8 -> 0 | H34: =H30*H8 -> 0 | I34: =I30*I8 -> 0 | ... M34: =M30*M8 -> 0
A35: Total Gross Profit | B35: =SUM(B32:B34) -> 1250 | C35: =SUM(C32:C34) -> 1500 | D35: =SUM(D32:D34) -> 1700 | E35: =SUM(E32:E34) -> 1900 | F35: =SUM(F32:F34) -> 2000 | G35: =SUM(G32:G34) -> 2100 | H35: =SUM(H32:H34) -> 2500 | I35: =SUM(I32:I34) -> 2750 | ... N35: =SUM(N32:N34) -> 31450

Sheet Operating Expenses (12 monts)
A1: Operating Expenses Forecasting 1-Year (2023)
A2: [Company's Name] [Forecast Start Date]
B3: Jan | C3: Feb | D3: Mar | E3: Apr | F3: May | G3: Jun | H3: Jul | I3: Aug | J3: Sep | K3: Oct | L3: Nov | M3: Dec | N3: 1-Year
A4: Operating Expenses
A5: General Adminstration
A6: Accessories(computer,air-con,table..) | B6: 2000 | C6: 0 | D6: 0 | E6: 0 | F6: 0 | G6: 0 | H6: 0 | I6: 0 | J6: 0 | K6: 0 | L6: 0 | M6: 0 | N6: =SUM(B6:M6) -> 2000
A7: App Develop | B7: 500 | C7: 0 | D7: 0 | E7: 0 | F7: 0 | G7: 0 | H7: 0 | I7: 0 | J7: 0 | K7: 0 | L7: 0 | M7: 0 | N7: =SUM(B7:M7) -> 500
A8: IT, Admin, Finance | B8: 1300 | C8: 1300 | D8: 1300 | E8: 1300 | F8: 1300 | G8: 1300 | H8: 1300 | I8: 1300 | J8: 1300 | K8: 1300 | L8: 1300 | M8: 1300 | N8: =SUM(B8:M8) -> 15600
A9: Payment Fee | B9: 100 | C9: 100 | D9: 100 | E9: 100 | F9: 100 | G9: 100 | H9: 100 | I9: 100 | J9: 100 | K9: 100 | L9: 100 | M9: 100 | N9: =SUM(B9:M9) -> 1200
A10: Renting workplace | B10: 200 | C10: 200 | D10: 200 | E10: 200 | F10: 200 | G10: 200 | H10: 200 | I10: 200 | J10: 200 | K10: 200 | L10: 200 | M10: 200 | N10: =SUM(B10:M10) -> 2400
A11: Marketing and Advertisement
A12: Product validation, product market fit | B12: 50 | C12: 50 | D12: 50 | E12: 0 | F12: 0 | G12: 0 | H12: 0 | I12: 50 | J12: 50 | K12: 0 | L12: 0 | M12: 0 | N12: =SUM(B12:M12) -> 250
A13: Logo design | B13: 50 | C13: 0 | D13: 0 | E13: 0 | F13: 0 | G13: 0 | H13: 0 | I13: 0 | J13: 0 | K13: 0 | L13: 0 | M13: 0 | N13: =SUM(B13:M13) -> 50
A14: Marketing materials | B14: 100 | C14: 100 | D14: 100 | E14: 100 | F14: 100 | G14: 100 | H14: 100 | I14: 100 | J14: 100 | K14: 100 | L14: 100 | M14: 100 | N14: =SUM(B14:M14) -> 1200
A15: PR, Advertisement fee | B15: 100 | C15: 100 | D15: 100 | E15: 100 | F15: 100 | G15: 100 | H15: 100 | I15: 100 | J15: 100 | K15: 100 | L15: 100 | M15: 100 | N15: =SUM(B15:M15) -> 1200
A16: Total Operating Expenses | B16: =SUM(B5:B15) -> 4400 | C16: =SUM(C5:C15) -> 1850 | D16: =SUM(D5:D15) -> 1850 | E16: =SUM(E5:E15) -> 1800 | F16: =SUM(F5:F15) -> 1800 | G16: =SUM(G5:G15) -> 1800 | H16: =SUM(H5:H15) -> 1800 | I16: =SUM(I5:I15) -> 1850 | ... N16: =SUM(N5:N15) -> 24400

Sheet P&L Statement
A1: Profit and Loss Statement
A2: [Company's Name] Period: 2023-2027
B4: 2023 | C4: 2024 | D4: 2025 | E4: 2026 | F4: 2027
A5: TOTAL SALE REVENUE ( A ) | B5: ='Sale Forecasting (12 months)'!N17 -> 125800
A6: TOTAL COST OF SALE ( B ) | B6: ='Sale Forecasting (12 months)'!N26 -> 94350
A7: GROSS PROFIT ( C = A - B ) | B7: =B5-B6 -> 31450
A8: Payment fees | B8: ='Operating Expenses (12 monts)'!N6 -> 2000
A9: Travel cost | B9: ='Operating Expenses (12 monts)'!N7 -> 500
A10: Education, Training fee | B10: ='Operating Expenses (12 monts)'!N8 -> 15600
A11: Stationary and overhead cost | B11: ='Operating Expenses (12 monts)'!N9 -> 1200
A12: Renting workplace | B12: ='Operating Expenses (12 monts)'!N10 -> 2400
A13: Product validation, product market fit | B13: ='Operating Expenses (12 monts)'!N12 -> 250
A14: Logo design | B14: ='Operating Expenses (12 monts)'!N13 -> 50
A15: Marketing materials | B15: ='Operating Expenses (12 monts)'!N14 -> 1200
A16: PR, Advertisement fee | B16: ='Operating Expenses (12 monts)'!N15 -> 1200
A17: OPERATION EXPENSE (D) | B17: =SUM(B8:B16) -> 24400
A18: OPERATING INCOME (E= C - D) | B18: =B7-B17 -> 7050
A19: OTHER INCOME (F) | B19: 0
A20: VAT (10% of revenue) | B20: =B5*0.1 -> 12580
A21: TOTAL TAXES (G) | B21: =SUM(B20) -> 12580
A22: NET PROFIT ( H = E + F - G) | B22: =B18+B19-B21 -> -5530

Sheet P&L Forecasting (12 Months)
A1: Profit and Loss Forecasting 1-Year (2023)
A2: [Company's Name] Profit and Loss Projection (12 months)
B3: Jan | C3: Feb | D3: Mar | E3: Apr | F3: May | G3: Jun | H3: Jul | I3: Aug | J3: Sep | K3: Oct | L3: Nov | M3: Dec | N3: 1-Year
A4: Sale Revenue
A5: Units Sold | N5: Total Units Sold
A6: Product/Service A | B6: ='Sale Forecasting (12 months)'!B6 -> 250 | C6: ='Sale Forecasting (12 months)'!C6 -> 300 | D6: ='Sale Forecasting (12 months)'!D6 -> 340 | E6: ='Sale Forecasting (12 months)'!E6 -> 380 | F6: ='Sale Forecasting (12 months)'!F6 -> 400 | G6: ='Sale Forecasting (12 months)'!G6 -> 420 | H6: ='Sale Forecasting (12 months)'!H6 -> 500 | I6: ='Sale Forecasting (12 months)'!I6 -> 550 | ... N6: ='Sale Forecasting (12 months)'!N6 -> 6290
A7: Product/Service B | B7: ='Sale Forecasting (12 months)'!B7 -> 0 | C7: ='Sale Forecasting (12 months)'!C7 -> 0 | D7: ='Sale Forecasting (12 months)'!D7 -> 0 | E7: ='Sale Forecasting (12 months)'!E7 -> 0 | F7: ='Sale Forecasting (12 months)'!F7 -> 0 | G7: ='Sale Forecasting (12 months)'!G7 -> 0 | H7: ='Sale Forecasting (12 months)'!H7 -> 0 | I7: ='Sale Forecasting (12 months)'!I7 -> 0 | ... N7: ='Sale Forecasting (12 months)'!N7 -> 0
A8: Product/Service C | B8: ='Sale Forecasting (12 months)'!B8 -> 0 | C8: ='Sale Forecasting (12 months)'!C8 -> 0 | D8: ='Sale Forecasting (12 months)'!D8 -> 0 | E8: ='Sale Forecasting (12 months)'!E8 -> 0 | F8: ='Sale Forecasting (12 months)'!F8 -> 0 | G8: ='Sale Forecasting (12 months)'!G8 -> 0 | H8: ='Sale Forecasting (12 months)'!H8 -> 0 | I8: ='Sale Forecasting (12 months)'!I8 -> 0 | ... N8: ='Sale Forecasting (12 months)'!N8 -> 0
A9: Unit Price | N9: Avg Unit Price
A10: Product/Service A | B10: ='Sale Forecasting (12 months)'!B10 -> 20 | C10: ='Sale Forecasting (12 months)'!C10 -> 20 | D10: ='Sale Forecasting (12 months)'!D10 -> 20 | E10: ='Sale Forecasting (12 months)'!E10 -> 20 | F10: ='Sale Forecasting (12 months)'!F10 -> 20 | G10: ='Sale Forecasting (12 months)'!G10 -> 20 | H10: ='Sale Forecasting (12 months)'!H10 -> 20 | I10: ='Sale Forecasting (12 months)'!I10 -> 20 | ... N10: ='Sale Forecasting (12 months)'!N10 -> 20
A11: Product/Service B | B11: ='Sale Forecasting (12 months)'!B11 -> 0 | C11: ='Sale Forecasting (12 months)'!C11 -> 0 | D11: ='Sale Forecasting (12 months)'!D11 -> 0 | E11: ='Sale Forecasting (12 months)'!E11 -> 0 | F11: ='Sale Forecasting (12 months)'!F11 -> 0 | G11: ='Sale Forecasting (12 months)'!G11 -> 0 | H11: ='Sale Forecasting (12 months)'!H11 -> 0 | I11: ='Sale Forecasting (12 months)'!I11 -> 0 | ... N11: ='Sale Forecasting (12 months)'!N11 -> 0
A12: Product/Service C | B12: ='Sale Forecasting (12 months)'!B12 -> 0 | C12: ='Sale Forecasting (12 months)'!C12 -> 0 | D12: ='Sale Forecasting (12 months)'!D12 -> 0 | E12: ='Sale Forecasting (12 months)'!E12 -> 0 | F12: ='Sale Forecasting (12 months)'!F12 -> 0 | G12: ='Sale Forecasting (12 months)'!G12 -> 0 | H12: ='Sale Forecasting (12 months)'!H12 -> 0 | I12: ='Sale Forecasting (12 months)'!I12 -> 0 | ... N12: ='Sale Forecasting (12 months)'!N12 -> 0
A13: Revenue | B13: (Units Sold * Unit Price) | N13: Total Revenue
A14: Product/Service A | B14: ='Sale Forecasting (12 months)'!B14 -> 5000 | C14: ='Sale Forecasting (12 months)'!C14 -> 6000 | D14: ='Sale Forecasting (12 months)'!D14 -> 6800 | E14: ='Sale Forecasting (12 months)'!E14 -> 7600 | F14: ='Sale Forecasting (12 months)'!F14 -> 8000 | G14: ='Sale Forecasting (12 months)'!G14 -> 8400 | H14: ='Sale Forecasting (12 months)'!H14 -> 10000 | I14: ='Sale Forecasting (12 months)'!I14 -> 11000 | ... N14: ='Sale Forecasting (12 months)'!N14 -> 125800
A15: Product/Service B | B15: ='Sale Forecasting (12 months)'!B15 -> 0 | C15: ='Sale Forecasting (12 months)'!C15 -> 0 | D15: ='Sale Forecasting (12 months)'!D15 -> 0 | E15: ='Sale Forecasting (12 months)'!E15 -> 0 | F15: ='Sale Forecasting (12 months)'!F15 -> 0 | G15: ='Sale Forecasting (12 months)'!G15 -> 0 | H15: ='Sale Forecasting (12 months)'!H15 -> 0 | I15: ='Sale Forecasting (12 months)'!I15 -> 0 | ... N15: ='Sale Forecasting (12 months)'!N15 -> 0
A16: Product/Service C | B16: ='Sale Forecasting (12 months)'!B16 -> 0 | C16: ='Sale Forecasting (12 months)'!C16 -> 0 | D16: ='Sale Forecasting (12 months)'!D16 -> 0 | E16: ='Sale Forecasting (12 months)'!E16 -> 0 | F16: ='Sale Forecasting (12 months)'!F16 -> 0 | G16: ='Sale Forecasting (12 months)'!G16 -> 0 | H16: ='Sale Forecasting (12 months)'!H16 -> 0 | I16: ='Sale Forecasting (12 months)'!I16 -> 0 | ... N16: ='Sale Forecasting (12 months)'!N16 -> 0
A17: Total Revenue | B17: ='Sale Forecasting (12 months)'!B17 -> 5000 | C17: ='Sale Forecasting (12 months)'!C17 -> 6000 | D17: ='Sale Forecasting (12 months)'!D17 -> 6800 | E17: ='Sale Forecasting (12 months)'!E17 -> 7600 | F17: ='Sale Forecasting (12 months)'!F17 -> 8000 | G17: ='Sale Forecasting (12 months)'!G17 -> 8400 | H17: ='Sale Forecasting (12 months)'!H17 -> 10000 | I17: ='Sale Forecasting (12 months)'!I17 -> 11000 | ... N17: ='Sale Forecasting (12 months)'!N17 -> 125800
A18: Unit COGS (Cost of Good Sold) | N18: Avg COGS
A19: Product/Service A | B19: ='Sale Forecasting (12 months)'!B19 -> 15 | C19: ='Sale Forecasting (12 months)'!C19 -> 15 | D19: ='Sale Forecasting (12 months)'!D19 -> 15 | E19: ='Sale Forecasting (12 months)'!E19 -> 15 | F19: ='Sale Forecasting (12 months)'!F19 -> 15 | G19: ='Sale Forecasting (12 months)'!G19 -> 15 | H19: ='Sale Forecasting (12 months)'!H19 -> 15 | I19: ='Sale Forecasting (12 months)'!I19 -> 15 | ... N19: ='Sale Forecasting (12 months)'!N19 -> 15
A20: Product/Service B | B20: ='Sale Forecasting (12 months)'!B20 -> 0 | C20: ='Sale Forecasting (12 months)'!C20 -> 0 | D20: ='Sale Forecasting (12 months)'!D20 -> 0 | E20: ='Sale Forecasting (12 months)'!E20 -> 0 | F20: ='Sale Forecasting (12 months)'!F20 -> 0 | G20: ='Sale Forecasting (12 months)'!G20 -> 0 | H20: ='Sale Forecasting (12 months)'!H20 -> 0 | I20: ='Sale Forecasting (12 months)'!I20 -> 0 | ... N20: ='Sale Forecasting (12 months)'!N20 -> 0
A21: Product/Service C | B21: ='Sale Forecasting (12 months)'!B21 -> 0 | C21: ='Sale Forecasting (12 months)'!C21 -> 0 | D21: ='Sale Forecasting (12 months)'!D21 -> 0 | E21: ='Sale Forecasting (12 months)'!E21 -> 0 | F21: ='Sale Forecasting (12 months)'!F21 -> 0 | G21: ='Sale Forecasting (12 months)'!G21 -> 0 | H21: ='Sale Forecasting (12 months)'!H21 -> 0 | I21: ='Sale Forecasting (12 months)'!I21 -> 0 | ... N21: ='Sale Forecasting (12 months)'!N21 -> 0
A22: COGS | B22: (Units Sold * Unit COGS) | N22: Total COGS
A23: Product/Service A | B23: ='Sale Forecasting (12 months)'!B23 -> 3750 | C23: ='Sale Forecasting (12 months)'!C23 -> 4500 | D23: ='Sale Forecasting (12 months)'!D23 -> 5100 | E23: ='Sale Forecasting (12 months)'!E23 -> 5700 | F23: ='Sale Forecasting (12 months)'!F23 -> 6000 | G23: ='Sale Forecasting (12 months)'!G23 -> 6300 | H23: ='Sale Forecasting (12 months)'!H23 -> 7500 | I23: ='Sale Forecasting (12 months)'!I23 -> 8250 | ... N23: ='Sale Forecasting (12 months)'!N23 -> 94350
A24: Product/Service B | B24: ='Sale Forecasting (12 months)'!B24 -> 0 | C24: ='Sale Forecasting (12 months)'!C24 -> 0 | D24: ='Sale Forecasting (12 months)'!D24 -> 0 | E24: ='Sale Forecasting (12 months)'!E24 -> 0 | F24: ='Sale Forecasting (12 months)'!F24 -> 0 | G24: ='Sale Forecasting (12 months)'!G24 -> 0 | H24: ='Sale Forecasting (12 months)'!H24 -> 0 | I24: ='Sale Forecasting (12 months)'!I24 -> 0 | ... N24: ='Sale Forecasting (12 months)'!N24 -> 0
A25: Product/Service C | B25: ='Sale Forecasting (12 months)'!B25 -> 0 | C25: ='Sale Forecasting (12 months)'!C25 -> 0 | D25: ='Sale Forecasting (12 months)'!D25 -> 0 | E25: ='Sale Forecasting (12 months)'!E25 -> 0 | F25: ='Sale Forecasting (12 months)'!F25 -> 0 | G25: ='Sale Forecasting (12 months)'!G25 -> 0 | H25: ='Sale Forecasting (12 months)'!H25 -> 0 | I25: ='Sale Forecasting (12 months)'!I25 -> 0 | ... N25: ='Sale Forecasting (12 months)'!N25 -> 0
A26: Total COGS | B26: ='Sale Forecasting (12 months)'!B26 -> 3750 | C26: ='Sale Forecasting (12 months)'!C26 -> 4500 | D26: ='Sale Forecasting (12 months)'!D26 -> 5100 | E26: ='Sale Forecasting (12 months)'!E26 -> 5700 | F26: ='Sale Forecasting (12 months)'!F26 -> 6000 | G26: ='Sale Forecasting (12 months)'!G26 -> 6300 | H26: ='Sale Forecasting (12 months)'!H26 -> 7500 | I26: ='Sale Forecasting (12 months)'!I26 -> 8250 | ... N26: ='Sale Forecasting (12 months)'!N26 -> 94350
A27: Margin Per Unit | B27: (Unit Price - Unit COGS) | N27: Avg Margin
A28: Product/Service A | B28: ='Sale Forecasting (12 months)'!B28 -> 5 | C28: ='Sale Forecasting (12 months)'!C28 -> 5 | D28: ='Sale Forecasting (12 months)'!D28 -> 5 | E28: ='Sale Forecasting (12 months)'!E28 -> 5 | F28: ='Sale Forecasting (12 months)'!F28 -> 5 | G28: ='Sale Forecasting (12 months)'!G28 -> 5 | H28: ='Sale Forecasting (12 months)'!H28 -> 5 | I28: ='Sale Forecasting (12 months)'!I28 -> 5 | ... N28: ='Sale Forecasting (12 months)'!N28 -> 5
A29: Product/Service B | B29: ='Sale Forecasting (12 months)'!B29 -> 0 | C29: ='Sale Forecasting (12 months)'!C29 -> 0 | D29: ='Sale Forecasting (12 months)'!D29 -> 0 | E29: ='Sale Forecasting (12 months)'!E29 -> 0 | F29: ='Sale Forecasting (12 months)'!F29 -> 0 | G29: ='Sale Forecasting (12 months)'!G29 -> 0 | H29: ='Sale Forecasting (12 months)'!H29 -> 0 | I29: ='Sale Forecasting (12 months)'!I29 -> 0 | ... N29: ='Sale Forecasting (12 months)'!N29 -> 0
A30: Product/Service C | B30: ='Sale Forecasting (12 months)'!B30 -> 0 | C30: ='Sale Forecasting (12 months)'!C30 -> 0 | D30: ='Sale Forecasting (12 months)'!D30 -> 0 | E30: ='Sale Forecasting (12 months)'!E30 -> 0 | F30: ='Sale Forecasting (12 months)'!F30 -> 0 | G30: ='Sale Forecasting (12 months)'!G30 -> 0 | H30: ='Sale Forecasting (12 months)'!H30 -> 0 | I30: ='Sale Forecasting (12 months)'!I30 -> 0 | ... N30: ='Sale Forecasting (12 months)'!N30 -> 0
A31: Gross Profit | B31: (Revenue - COGS or Margin Per Unit * Unit Sold) | N31: Total Gross Profit
A32: Product/Service A | B32: ='Sale Forecasting (12 months)'!B32 -> 1250 | C32: ='Sale Forecasting (12 months)'!C32 -> 1500 | D32: ='Sale Forecasting (12 months)'!D32 -> 1700 | E32: ='Sale Forecasting (12 months)'!E32 -> 1900 | F32: ='Sale Forecasting (12 months)'!F32 -> 2000 | G32: ='Sale Forecasting (12 months)'!G32 -> 2100 | H32: ='Sale Forecasting (12 months)'!H32 -> 2500 | I32: ='Sale Forecasting (12 months)'!I32 -> 2750 | ... N32: ='Sale Forecasting (12 months)'!N32 -> 31450
A33: Product/Service B | B33: ='Sale Forecasting (12 months)'!B33 -> 0 | C33: ='Sale Forecasting (12 months)'!C33 -> 0 | D33: ='Sale Forecasting (12 months)'!D33 -> 0 | E33: ='Sale Forecasting (12 months)'!E33 -> 0 | F33: ='Sale Forecasting (12 months)'!F33 -> 0 | G33: ='Sale Forecasting (12 months)'!G33 -> 0 | H33: ='Sale Forecasting (12 months)'!H33 -> 0 | I33: ='Sale Forecasting (12 months)'!I33 -> 0 | ... N33: ='Sale Forecasting (12 months)'!N33 -> 0
A34: Product/Service C | B34: ='Sale Forecasting (12 months)'!B34 -> 0 | C34: ='Sale Forecasting (12 months)'!C34 -> 0 | D34: ='Sale Forecasting (12 months)'!D34 -> 0 | E34: ='Sale Forecasting (12 months)'!E34 -> 0 | F34: ='Sale Forecasting (12 months)'!F34 -> 0 | G34: ='Sale Forecasting (12 months)'!G34 -> 0 | H34: ='Sale Forecasting (12 months)'!H34 -> 0 | I34: ='Sale Forecasting (12 months)'!I34 -> 0 | ... N34: ='Sale Forecasting (12 months)'!N34 -> 0
A35: Total Gross Profit | B35: ='Sale Forecasting (12 months)'!B35 -> 1250 | C35: ='Sale Forecasting (12 months)'!C35 -> 1500 | D35: ='Sale Forecasting (12 months)'!D35 -> 1700 | E35: ='Sale Forecasting (12 months)'!E35 -> 1900 | F35: ='Sale Forecasting (12 months)'!F35 -> 2000 | G35: ='Sale Forecasting (12 months)'!G35 -> 2100 | H35: ='Sale Forecasting (12 months)'!H35 -> 2500 | I35: ='Sale Forecasting (12 months)'!I35 -> 2750 | ... N35: ='Sale Forecasting (12 months)'!N35 -> 31450
A36: Operating Expenses
A37: General Adminstration | N37: Total GA
A38: Payment fees | B38: ='Operating Expenses (12 monts)'!B6 -> 2000 | C38: ='Operating Expenses (12 monts)'!C6 -> 0 | D38: ='Operating Expenses (12 monts)'!D6 -> 0 | E38: ='Operating Expenses (12 monts)'!E6 -> 0 | F38: ='Operating Expenses (12 monts)'!F6 -> 0 | G38: ='Operating Expenses (12 monts)'!G6 -> 0 | H38: ='Operating Expenses (12 monts)'!H6 -> 0 | I38: ='Operating Expenses (12 monts)'!I6 -> 0 | ... N38: ='Operating Expenses (12 monts)'!N6 -> 2000
A39: Travel cost | B39: ='Operating Expenses (12 monts)'!B7 -> 500 | C39: ='Operating Expenses (12 monts)'!C7 -> 0 | D39: ='Operating Expenses (12 monts)'!D7 -> 0 | E39: ='Operating Expenses (12 monts)'!E7 -> 0 | F39: ='Operating Expenses (12 monts)'!F7 -> 0 | G39: ='Operating Expenses (12 monts)'!G7 -> 0 | H39: ='Operating Expenses (12 monts)'!H7 -> 0 | I39: ='Operating Expenses (12 monts)'!I7 -> 0 | ... N39: ='Operating Expenses (12 monts)'!N7 -> 500
A40: Education, Training fee | B40: ='Operating Expenses (12 monts)'!B8 -> 1300 | C40: ='Operating Expenses (12 monts)'!C8 -> 1300 | D40: ='Operating Expenses (12 monts)'!D8 -> 1300 | E40: ='Operating Expenses (12 monts)'!E8 -> 1300 | F40: ='Operating Expenses (12 monts)'!F8 -> 1300 | G40: ='Operating Expenses (12 monts)'!G8 -> 1300 | H40: ='Operating Expenses (12 monts)'!H8 -> 1300 | I40: ='Operating Expenses (12 monts)'!I8 -> 1300 | ... N40: ='Operating Expenses (12 monts)'!N8 -> 15600
...

Sheet Start-up Funding
A1: Sources and Uses of Funds
A3: Sources of Funds
A4: No | B4: Sources of Funds | C4: Amount
A5: 1 | B5: Personal Investment | C5: 0
A6: 2 | B6: Angel investor | C6: 0
A7: 3 | B7: Venture Capital | C7: 0
A8: 4 | B8: Business Incubators | C8: 0
A9: 5 | B9: Corporate Seed Funds | C9: 0
A10: 6 | B10: Bank Loans | C10: 0
A11: Total | C11: =SUM(C4:C10) -> 0
